nohup: ignoring input
[2025-07-04 22:28:26] INFO üöÄ D√©marrage du bot NONO en environnement MAINNET
[2025-07-04 22:28:26] INFO ‚ñ∂Ô∏è Connexion WS (mainnet) √† wss://mainnet.helius-rpc.com/?api-key=75c7c75c-0230-482e-af0e-f2860324e474
Traceback (most recent call last):
  File "/mnt/w/local/nono/newvenv/lib/python3.12/site-packages/websockets/legacy/protocol.py", line 968, in transfer_data
    message = await self.read_message()
              ^^^^^^^^^^^^^^^^^^^^^^^^^
  File "/mnt/w/local/nono/newvenv/lib/python3.12/site-packages/websockets/legacy/protocol.py", line 1038, in read_message
    frame = await self.read_data_frame(max_size=self.max_size)
            ^^^^^^^^^^^^^^^^^^^^^^^^^^^^^^^^^^^^^^^^^^^^^^^^^^
  File "/mnt/w/local/nono/newvenv/lib/python3.12/site-packages/websockets/legacy/protocol.py", line 1113, in read_data_frame
    frame = await self.read_frame(max_size)
            ^^^^^^^^^^^^^^^^^^^^^^^^^^^^^^^
  File "/mnt/w/local/nono/newvenv/lib/python3.12/site-packages/websockets/legacy/protocol.py", line 1170, in read_frame
    frame = await Frame.read(
            ^^^^^^^^^^^^^^^^^
  File "/mnt/w/local/nono/newvenv/lib/python3.12/site-packages/websockets/legacy/framing.py", line 69, in read
    data = await reader(2)
           ^^^^^^^^^^^^^^^
  File "/home/captain/.pyenv/versions/3.12.3/lib/python3.12/asyncio/streams.py", line 752, in readexactly
    await self._wait_for_data('readexactly')
  File "/home/captain/.pyenv/versions/3.12.3/lib/python3.12/asyncio/streams.py", line 545, in _wait_for_data
    await self._waiter
  File "/home/captain/.pyenv/versions/3.12.3/lib/python3.12/asyncio/selector_events.py", line 988, in _read_ready__get_buffer
    nbytes = self._sock.recv_into(buf)
             ^^^^^^^^^^^^^^^^^^^^^^^^^
ConnectionResetError: [Errno 104] Connection reset by peer

The above exception was the direct cause of the following exception:

Traceback (most recent call last):
  File "/mnt/w/local/nono/main.py", line 97, in <module>
    import websockets
    ^^^^^^^^^^^^^^^^^^
  File "/home/captain/.pyenv/versions/3.12.3/lib/python3.12/asyncio/runners.py", line 194, in run
    return runner.run(main)
           ^^^^^^^^^^^^^^^^
  File "/home/captain/.pyenv/versions/3.12.3/lib/python3.12/asyncio/runners.py", line 118, in run
    return self._loop.run_until_complete(task)
           ^^^^^^^^^^^^^^^^^^^^^^^^^^^^^^^^^^^
  File "/home/captain/.pyenv/versions/3.12.3/lib/python3.12/asyncio/base_events.py", line 687, in run_until_complete
    return future.result()
           ^^^^^^^^^^^^^^^
  File "/mnt/w/local/nono/main.py", line 94, in main
    log.warning(f"Erreur envoi stats: {e}")
^^^^^^^^^^^^^^^^^^^^^^^^^^^^^^^^^^
  File "/mnt/w/local/nono/main.py", line 43, in websocket_listener
    async def get_volatility_estimate(_):
            ^^^^^^^^^^^^^^^^^^^^^^^^^^^^^
  File "/mnt/w/local/nono/newvenv/lib/python3.12/site-packages/websockets/legacy/protocol.py", line 497, in __aiter__
    yield await self.recv()
          ^^^^^^^^^^^^^^^^^
  File "/mnt/w/local/nono/newvenv/lib/python3.12/site-packages/websockets/legacy/protocol.py", line 568, in recv
    await self.ensure_open()
  File "/mnt/w/local/nono/newvenv/lib/python3.12/site-packages/websockets/legacy/protocol.py", line 944, in ensure_open
    raise self.connection_closed_exc()
websockets.exceptions.ConnectionClosedError: no close frame received or sent
